<?xml version="1.0" encoding="utf-8"?>
<mujoco>
    <compiler angle="radian" coordinate="local" meshdir="../stls/ur5e_handlite" texturedir="../textures"></compiler>
    <option timestep="0.002" iterations="20" apirate="200" gravity='0 0 -9.81'>
        <flag warmstart="enable"></flag>
    </option>

    <include file="door_shared.xml"></include>

    <asset>
        <include file="door_shared_asset.xml"></include>


 
        <texture name="texture:object" file="block.png" gridsize="3 4" gridlayout=".U..LFRB.D.."></texture>
        <texture name="texture:hidden" file="block_hidden.png" gridsize="3 4" gridlayout=".U..LFRB.D.."></texture>
        <material name="material:object" texture="texture:object" specular="1" shininess="0.3" reflectance="0"></material>
        <material name="material:hidden" texture="texture:hidden" specular="1" shininess="0.3" reflectance="0"></material>
        <material name="material:target" texture="texture:object" specular="1" shininess="0.3" reflectance="0" rgba="1 1 1 0.5"></material>

        <texture type="cube" name="foil" file="silverRaw.png" />
        <texture type="cube" name="wood" file="wood.png" />
        <material name="MatWood" texture="wood" texrepeat="3 3" specular="0.4" shininess="0.1" />
        <material name="MatFoil" texture="foil" specular="1" shininess="0.3" rgba="0.9 0.9 0.9 1" />
    </asset>

    <include file="table/asset.xml"/>





    <worldbody>
        <include file="env_asset.xml"></include>


       <include file="ur5e.xml"></include>

        <!-- ======= DOOR ======= -->
        <body name="frame" pos="-0.3 0.9 1.2" user="1001 0 2002 -0.4 -0.1 0.252 0 0.3 0.45">
            <inertial pos="0.29 0 0" quat="0.5 0.5 0.5 0.5" mass="7.85398" diaginertia="0.923301 0.764585 0.168533" />
            <geom size="0.05 0.25" pos="0.6 0 0" type="cylinder" material="MatWood" rgba="1 0 0 1" />
            <geom size="0.05 0.25" pos="-0.02 0 0" type="cylinder" material="MatWood" rgba="1 0 0 1" />
            <site name="S_handle_target" pos="0.75 -0.5 -.18" size="0.025" group='3'/>
            <body name="door" pos="0.29 0 0">
                <inertial pos="0.0296816 -0.00152345 0" quat="0.701072 0 0 0.713091" mass="2.43455" diaginertia="0.0913751 0.0521615 0.043714" />
                <joint name="door_hinge" pos="0.31 0 0" axis="0 0 1" range="0 1.57" damping="1" frictionloss="2" />
                <geom size="0.2 0.05 0.25" type="box" friction="1 1 1" material="MatWood" />
                <geom size="0.05 0.25" pos="0.2 0 0" type="cylinder" material="MatWood" />
                <geom size="0.05 0.25" pos="-0.2 0 0" type="cylinder" material="MatWood" />
                <body name="latch" pos="-0.15 0 -0.025">
                    <inertial pos="-0.017762 0.0138544 0" quat="0.365653 0.605347 -0.36522 0.605365" mass="3.53743" diaginertia="0.0483771 0.0410001 0.0111013" />
                    <joint name="latch" pos="0 0 0" axis="0 1 0" range="0 1.8" frictionloss="5" />
                    <geom size="0.05 0.15" quat="0.707388 0.706825 0 0" type="cylinder" material="MatFoil" />
                    <geom size="0.02 0.1" pos="0.1 -0.15 0" quat="0.707388 0 0.706825 0" type="capsule" material="MatFoil" />
                    <geom size="0.04 0.07" pos="-0.1 0.1 0" quat="0.707388 0 0.706825 0" type="capsule" material="MatFoil" />
                    <site name="S_handle" pos="0.15 -0.15 0" size="0.025" group='3'/>
                </body>
            </body>
        </body>



        <!--<body name="egg" pos="1 0.87 0.2">-->
            <!--<geom name="object" type="ellipsoid" size="0.03 0.03 0.04" material="material:object" condim="4"></geom>-->
            <!--<geom name="object_hidden" type="ellipsoid" size="0.029 0.029 0.03" material="material:hidden" condim="4" contype="0" conaffinity="0" mass="0"></geom>-->
            <!--<site name="egg1" pos="0 0 0" rgba="1 0 0 0" size="0.01 0.01 0.01"></site>-->
            <!--<joint name="Jegg1" type="free" damping="0.01"></joint>-->
        <!--</body>-->
        <body name="target" pos="1 0.87 0.2">
            <geom name="target" type="ellipsoid" size="0.03 0.03 0.04" material="material:target" condim="4" group="2" contype="0" conaffinity="0"></geom>
            <site name="target:center" pos="0 0 0" rgba="1 0 0 0" size="0.01 0.01 0.01"></site>
            <joint name="target:joint" type="free" damping="0.01"></joint>
        </body>

    </worldbody>

     <equality>
        <weld body1="robot0:mocap" body2="ee_link" solimp="0.9 0.95 0.001" solref="0.02 1"></weld>
    </equality>

</mujoco>
